<?xml version="1.0" ?>
<robot name="mobile" xmlns:xacro="http://www.ros.org/wiki/xacro">

<xacro:include filename="$(find first_urdf)/urdf/materials.xacro" />
<xacro:include filename="$(find first_urdf)/urdf/mobile.trans" />
<xacro:include filename="$(find first_urdf)/urdf/mobile.gazebo" />
<link name="base_link">
  <inertial>
    <origin xyz="5.474970520392453e-15 -0.000301736895621843 0.01987626616510473" rpy="0 0 0"/>
    <mass value="9.467267879467137"/>
    <inertia ixx="0.032984" iyy="0.018991" izz="0.049394" ixy="0.0" iyz="-9.3e-05" ixz="0.0"/>
  </inertial>
  <visual>
    <origin xyz="0 0 0" rpy="0 0 0"/>
    <geometry>
      <mesh filename="file://$(find first_urdf)/meshes/base_link.stl" scale="0.001 0.001 0.001"/>
    </geometry>
    <material name="silver"/>
  </visual>
  <collision>
    <origin xyz="0 0 0" rpy="0 0 0"/>
    <geometry>
      <mesh filename="file://$(find first_urdf)/meshes/base_link.stl" scale="0.001 0.001 0.001"/>
    </geometry>
  </collision>
</link>

<link name="left_wheel_1">
  <inertial>
    <origin xyz="0.009999999999999995 0.0 -6.938893903907228e-18" rpy="0 0 0"/>
    <mass value="0.789168074581756"/>
    <inertia ixx="0.000631" iyy="0.000342" izz="0.000342" ixy="0.0" iyz="0.0" ixz="-0.0"/>
  </inertial>
  <visual>
    <origin xyz="-0.08 -0.07 -0.02" rpy="0 0 0"/>
    <geometry>
      <mesh filename="file://$(find first_urdf)/meshes/left_wheel_1.stl" scale="0.001 0.001 0.001"/>
    </geometry>
    <material name="silver"/>
  </visual>
  <collision>
    <origin xyz="-0.08 -0.07 -0.02" rpy="0 0 0"/>
    <geometry>
      <mesh filename="file://$(find first_urdf)/meshes/left_wheel_1.stl" scale="0.001 0.001 0.001"/>
    </geometry>
  </collision>
</link>

<link name="right_wheel_1">
  <inertial>
    <origin xyz="-0.009999999999999995 0.0 -6.938893903907228e-18" rpy="0 0 0"/>
    <mass value="0.789168074581756"/>
    <inertia ixx="0.000631" iyy="0.000342" izz="0.000342" ixy="0.0" iyz="0.0" ixz="0.0"/>
  </inertial>
  <visual>
    <origin xyz="0.08 -0.07 -0.02" rpy="0 0 0"/>
    <geometry>
      <mesh filename="file://$(find first_urdf)/meshes/right_wheel_1.stl" scale="0.001 0.001 0.001"/>
    </geometry>
    <material name="silver"/>
  </visual>
  <collision>
    <origin xyz="0.08 -0.07 -0.02" rpy="0 0 0"/>
    <geometry>
      <mesh filename="file://$(find first_urdf)/meshes/right_wheel_1.stl" scale="0.001 0.001 0.001"/>
    </geometry>
  </collision>
</link>

<joint name="Revolute 1" type="continuous">
  <origin xyz="0.08 0.07 0.02" rpy="0 0 0"/>
  <parent link="base_link"/>
  <child link="left_wheel_1"/>
  <axis xyz="1.0 0.0 0.0"/>
</joint>

<joint name="Revolute 2" type="continuous">
  <origin xyz="-0.08 0.07 0.02" rpy="0 0 0"/>
  <parent link="base_link"/>
  <child link="right_wheel_1"/>
  <axis xyz="-1.0 0.0 0.0"/>
</joint>

</robot>
